<mujoco model="franka_brainco_revo2_right">
  <compiler angle="radian" meshdir="/autodl-fs/data/mingyu/Mujoco/projects/franka_revo2_thrown_ball_cube_catch/assets/full_robot_urdf_mirror" />

  <option timestep="0.002" gravity="0 0 -9.81" integrator="implicitfast" iterations="80" /><asset>
    <mesh name="link0" file="link0_visual_aligned_v728.stl" />
    <mesh name="link1" file="link1_visual_aligned_v728.stl" />
    <mesh name="link2" file="link2_visual_aligned_v728.stl" />
    <mesh name="link3" file="link3_visual_aligned_v728.stl" />
    <mesh name="link4" file="link4_visual_aligned_v728.stl" />
    <mesh name="link5" file="link5_visual_aligned_v728.stl" />
    <mesh name="link6" file="link6_visual_aligned_v728.stl" />
    <mesh name="link7" file="link7_visual_aligned_v728.stl" />
    <mesh name="right_base_link" file="right_base_link.STL" />
    <mesh name="right_thumb_metacarpal_link" file="right_thumb_metacarpal_link.STL" />
    <mesh name="right_thumb_proximal_link" file="right_thumb_proximal_link.STL" />
    <mesh name="right_thumb_distal_link" file="right_thumb_distal_link.STL" />
    <mesh name="right_thumb_touch_link" file="right_thumb_touch_link.STL" />
    <mesh name="right_index_proximal_link" file="right_index_proximal_link.STL" />
    <mesh name="right_index_distal_link" file="right_index_distal_link.STL" />
    <mesh name="right_index_touch_link" file="right_index_touch_link.STL" />
    <mesh name="right_middle_proximal_link" file="right_middle_proximal_link.STL" />
    <mesh name="right_middle_distal_link" file="right_middle_distal_link.STL" />
    <mesh name="right_middle_touch_link" file="right_middle_touch_link.STL" />
    <mesh name="right_ring_proximal_link" file="right_ring_proximal_link.STL" />
    <mesh name="right_ring_distal_link" file="right_ring_distal_link.STL" />
    <mesh name="right_ring_touch_link" file="right_ring_touch_link.STL" />
    <mesh name="right_pinky_proximal_link" file="right_pinky_proximal_link.STL" />
    <mesh name="right_pinky_distal_link" file="right_pinky_distal_link.STL" />
    <mesh name="right_pinky_touch_link" file="right_pinky_touch_link.STL" />
  <texture name="video2sim_warm_wood_floor_tex" type="2d" builtin="checker" rgb1="0.74 0.50 0.28" rgb2="0.48 0.30 0.16" width="1024" height="1024" /><texture name="video2sim_soft_indoor_wall_tex" type="2d" builtin="checker" rgb1="0.78 0.75 0.68" rgb2="0.69 0.67 0.61" width="1024" height="1024" /><material name="video2sim_warm_wood_floor_mat" texture="video2sim_warm_wood_floor_tex" texrepeat="8 8" reflectance="0.18" specular="0.28" shininess="0.35" /><material name="video2sim_soft_indoor_wall_mat" texture="video2sim_soft_indoor_wall_tex" texrepeat="3 2" reflectance="0.08" specular="0.10" shininess="0.12" /></asset>

  <worldbody>
    <geom type="mesh" mesh="link0" contype="0" conaffinity="0" />
    <body name="panda_link1" pos="0 0 0.333" gravcomp="1">
      <joint name="panda_joint1" pos="0 0 0" axis="0 0 1" range="-2.8973 2.8973" actuatorfrcrange="-87 87" damping="4.0" armature="0.05" />
      <geom type="mesh" mesh="link1" contype="0" conaffinity="0" />
      <body name="panda_link2" quat="0.707107 -0.707107 0 0" gravcomp="1">
        <joint name="panda_joint2" pos="0 0 0" axis="0 0 1" range="-1.7628 1.7628" actuatorfrcrange="-87 87" damping="4.0" armature="0.05" />
        <geom type="mesh" mesh="link2" contype="0" conaffinity="0" />
        <body name="panda_link3" pos="0 -0.316 0" quat="0.707107 0.707107 0 0" gravcomp="1">
          <joint name="panda_joint3" pos="0 0 0" axis="0 0 1" range="-2.8973 2.8973" actuatorfrcrange="-87 87" damping="4.0" armature="0.05" />
          <geom type="mesh" mesh="link3" contype="0" conaffinity="0" />
          <body name="panda_link4" pos="0.0825 0 0" quat="0.707107 0.707107 0 0" gravcomp="1">
            <joint name="panda_joint4" pos="0 0 0" axis="0 0 1" range="-3.0718 -0.0698" actuatorfrcrange="-87 87" damping="4.0" armature="0.05" />
            <geom type="mesh" mesh="link4" contype="0" conaffinity="0" />
            <body name="panda_link5" pos="-0.0825 0.384 0" quat="0.707107 -0.707107 0 0" gravcomp="1">
              <joint name="panda_joint5" pos="0 0 0" axis="0 0 1" range="-2.8973 2.8973" actuatorfrcrange="-12 12" damping="4.0" armature="0.05" />
              <geom type="mesh" mesh="link5" contype="0" conaffinity="0" />
              <body name="panda_link6" quat="0.707107 0.707107 0 0" gravcomp="1">
                <joint name="panda_joint6" pos="0 0 0" axis="0 0 1" range="-0.0175 3.7525" actuatorfrcrange="-12 12" damping="4.0" armature="0.05" />
                <geom type="mesh" mesh="link6" contype="0" conaffinity="0" />
                <body name="panda_link7" pos="0.088 0 0" quat="0.707107 0.707107 0 0" gravcomp="1">
                  <joint name="panda_joint7" pos="0 0 0" axis="0 0 1" range="-2.8973 2.8973" actuatorfrcrange="-12 12" damping="4.0" armature="0.05" />
                  <geom type="mesh" mesh="link7" contype="0" conaffinity="0" />
                  <geom size="0.034 0.004" pos="0 0 0.111" quat="0.92388 0 0 -0.382683" type="cylinder" rgba="0.35 0.35 0.35 1" contype="0" conaffinity="0" />
                  <geom size="0.018 0.0212" pos="0 0 0.1362" quat="0.92388 0 0 -0.382683" type="cylinder" rgba="0.35 0.35 0.35 1" contype="0" conaffinity="0" />
                  <geom size="0.028 0.004" pos="0 0 0.1614" quat="0.92388 0 0 -0.382683" type="cylinder" rgba="0.35 0.35 0.35 1" contype="0" conaffinity="0" />
                  <geom pos="0 0 0.1654" quat="0.382683 0 0 0.92388" type="mesh" rgba="0.04 0.1 0.22 1" mesh="right_base_link" contype="0" conaffinity="0" />
                  <body name="revo2_right_thumb_metacarpal_link" pos="-0.0180213 -0.0100749 0.193225" quat="0.458791 0 0 0.888544" gravcomp="1">
                    <inertial pos="1.51106e-05 0.00707243 -0.00420847" quat="0.465075 -0.0302438 0.0586743 0.882807" mass="0.01" diaginertia="1.66115e-07 1.56006e-07 4.9387e-08" />
                    <joint name="revo2_right_thumb_metacarpal_joint" pos="0 0 0" axis="0 0 -1" range="0 1.57" actuatorfrcrange="-3.0 3.0" damping="0.55" armature="0.012" />
                    <geom type="mesh" rgba="0.04 0.1 0.22 1" mesh="right_thumb_metacarpal_link" contype="1" conaffinity="1" friction="5.2 0.95 0.100" condim="4" solref="0.008 1" solimp="0.93 0.998 0.001" />
                    <body name="revo2_right_thumb_proximal_link" pos="0 0.014227 0" quat="0.986557 0.0765206 0.124804 0.0726253" gravcomp="1">
                      <inertial pos="-4.6972e-07 0.0277015 -0.00202656" quat="0.496496 0.503512 -0.503514 0.496429" mass="0.05" diaginertia="2.56295e-06 2.40452e-06 5.11916e-07" />
                      <joint name="revo2_right_thumb_proximal_joint" pos="0 0 0" axis="1 0 0" range="0 1.03" actuatorfrcrange="-5.0 5.0" damping="0.55" armature="0.012" />
                      <geom type="mesh" rgba="0.04 0.1 0.22 1" mesh="right_thumb_proximal_link" contype="1" conaffinity="1" friction="5.2 0.95 0.100" condim="4" solref="0.008 1" solimp="0.93 0.998 0.001" />
                      <body name="revo2_right_thumb_distal_link" pos="0 0.052 0" gravcomp="1">
                        <inertial pos="-6.86982e-09 0.0117545 1.13288e-05" quat="0.528527 0.469685 -0.46966 0.528654" mass="0.012" diaginertia="4.42072e-07 3.35587e-07 2.27759e-07" />
                        <joint name="revo2_right_thumb_distal_joint" pos="0 0 0" axis="1 0 0" range="0 1.03" actuatorfrcrange="-5.0 5.0" damping="0.55" armature="0.012" />
                        <geom type="mesh" rgba="0.04 0.1 0.22 1" mesh="right_thumb_distal_link" contype="1" conaffinity="1" friction="5.2 0.95 0.100" condim="4" solref="0.008 1" solimp="0.93 0.998 0.001" />
                        <geom pos="0 0.0137928 0.0076766" quat="0.999443 -0.033369 0 0" type="mesh" rgba="0.18 0.18 0.2 1" mesh="right_thumb_touch_link" contype="1" conaffinity="1" friction="5.2 0.95 0.100" condim="4" solref="0.008 1" solimp="0.93 0.998 0.001" />
                        <geom size="0.012 0.009 0.013" pos="0 0.0127283 0.00674553" quat="0.999443 -0.033369 0 0" type="box" rgba="0.18 0.18 0.2 1" contype="1" conaffinity="1" friction="5.2 0.95 0.100" condim="4" solref="0.008 1" solimp="0.93 0.998 0.001" />
                      <geom name="stage4_thumb_tip_marker" type="sphere" pos="0 0.0127283 0.00674553" size="0.014" rgba="0 0 0 0" contype="0" conaffinity="0" /><geom name="video2sim_revo2_right_thumb_distal_link_contact_pad" type="sphere" group="5" pos="0.0000 0.0127 0.0067" size="0.021000" rgba="0.05 0.05 0.05 0.0" contype="1" conaffinity="1" friction="9.0 1.55 0.200" condim="4" solref="0.008 1" solimp="0.995 0.9999 0.0001" /><geom name="video2sim_revo2_right_thumb_distal_link_contact_pad_extra_0" type="sphere" group="5" pos="0.000000 0.012700 -0.007300" size="0.014000" rgba="0.05 0.05 0.05 0.0" contype="1" conaffinity="1" friction="9.0 1.55 0.200" condim="4" solref="0.014 1" solimp="0.96 0.999 0.001" /><geom name="video2sim_revo2_right_thumb_distal_link_contact_pad_extra_1" type="sphere" group="5" pos="0.000000 0.012700 0.020700" size="0.014000" rgba="0.05 0.05 0.05 0.0" contype="1" conaffinity="1" friction="9.0 1.55 0.200" condim="4" solref="0.014 1" solimp="0.96 0.999 0.001" /></body>
                    <geom name="video2sim_revo2_right_thumb_proximal_link_contact_pad" type="sphere" group="5" pos="0.0000 0.0279 -0.0022" size="0.020000" rgba="0.05 0.05 0.05 0.0" contype="1" conaffinity="1" friction="9.0 1.55 0.200" condim="4" solref="0.008 1" solimp="0.995 0.9999 0.0001" /></body>
                  </body>
                  <body name="revo2_right_index_proximal_link" pos="-0.01941 -0.0224055 0.246276" quat="0.455694 -0.092407 -0.018312 0.885138" gravcomp="1">
                    <inertial pos="-0.00223495 3.15875e-06 0.0176402" quat="0.9998 0.000578854 0.0200071 0.00015863" mass="0.009" diaginertia="2.52201e-07 2.36436e-07 9.27798e-08" />
                    <joint name="revo2_right_index_proximal_joint" pos="0 0 0" axis="0 1 0" range="0 1.41" actuatorfrcrange="-7.0 7.0" damping="0.55" armature="0.012" />
                    <geom type="mesh" rgba="0.04 0.1 0.22 1" mesh="right_index_proximal_link" contype="1" conaffinity="1" friction="5.2 0.95 0.100" condim="4" solref="0.008 1" solimp="0.93 0.998 0.001" />
                    <body name="revo2_right_index_distal_link" pos="0 0 0.032" gravcomp="1">
                      <inertial pos="0.00506251 1.61615e-07 0.0165189" quat="0.684726 0.176495 0.176496 0.684726" mass="0.011" diaginertia="7.85555e-07 7.71534e-07 8.73346e-08" />
                      <joint name="revo2_right_index_distal_joint" pos="0 0 0" axis="0 1 0" range="0 1.63" actuatorfrcrange="-7.0 7.0" damping="0.55" armature="0.012" />
                      <geom type="mesh" rgba="0.04 0.1 0.22 1" mesh="right_index_distal_link" contype="1" conaffinity="1" friction="5.2 0.95 0.100" condim="4" solref="0.008 1" solimp="0.93 0.998 0.001" />
                      <geom pos="0.014497 0 0.023303" quat="0.6361 0.734769 0.154182 -0.178098" type="mesh" rgba="0.18 0.18 0.2 1" mesh="right_index_touch_link" contype="1" conaffinity="1" friction="5.2 0.95 0.100" condim="4" solref="0.008 1" solimp="0.93 0.998 0.001" />
                      <geom size="0.011 0.009 0.013" pos="0.0131721 -0.00014321 0.0250986" quat="0.6361 0.734769 0.154182 -0.178098" type="box" rgba="0.18 0.18 0.2 1" contype="1" conaffinity="1" friction="5.2 0.95 0.100" condim="4" solref="0.008 1" solimp="0.93 0.998 0.001" />
                    <geom name="stage4_index_tip_marker" type="sphere" pos="0.0131721 -0.00014321 0.0250986" size="0.014" rgba="0 0 0 0" contype="0" conaffinity="0" /><geom name="video2sim_revo2_right_index_distal_link_contact_pad" type="sphere" group="5" pos="0.0132 -0.0001 0.0251" size="0.021000" rgba="0.05 0.05 0.05 0.0" contype="1" conaffinity="1" friction="9.0 1.55 0.200" condim="4" solref="0.008 1" solimp="0.995 0.9999 0.0001" /><geom name="video2sim_revo2_right_index_distal_link_contact_pad_extra_0" type="sphere" group="5" pos="0.013200 -0.000100 0.011100" size="0.014000" rgba="0.05 0.05 0.05 0.0" contype="1" conaffinity="1" friction="9.0 1.55 0.200" condim="4" solref="0.014 1" solimp="0.96 0.999 0.001" /><geom name="video2sim_revo2_right_index_distal_link_contact_pad_extra_1" type="sphere" group="5" pos="0.013200 -0.000100 0.039100" size="0.014000" rgba="0.05 0.05 0.05 0.0" contype="1" conaffinity="1" friction="9.0 1.55 0.200" condim="4" solref="0.014 1" solimp="0.96 0.999 0.001" /></body>
                  <geom name="video2sim_revo2_right_index_proximal_link_contact_pad" type="sphere" group="5" pos="-0.0021 0.0000 0.0174" size="0.020000" rgba="0.05 0.05 0.05 0.0" contype="1" conaffinity="1" friction="9.0 1.55 0.200" condim="4" solref="0.008 1" solimp="0.995 0.9999 0.0001" /></body>
                  <body name="revo2_right_middle_proximal_link" pos="-0.00387091 -0.0103433 0.250393" quat="0.406762 -0.0756337 0.0123612 0.910314" gravcomp="1">
                    <inertial pos="-0.00222511 5.25632e-06 0.0203008" quat="0.999816 0.00054813 0.0191911 0.000563992" mass="0.009" diaginertia="3.67373e-07 3.52646e-07 1.11857e-07" />
                    <joint name="revo2_right_middle_proximal_joint" pos="0 0 0" axis="0 1 0" range="0 1.41" actuatorfrcrange="-7.0 7.0" damping="0.55" armature="0.012" />
                    <geom type="mesh" rgba="0.04 0.1 0.22 1" mesh="right_middle_proximal_link" contype="1" conaffinity="1" friction="5.2 0.95 0.100" condim="4" solref="0.008 1" solimp="0.93 0.998 0.001" />
                    <body name="revo2_right_middle_distal_link" pos="0 0 0.037" gravcomp="1">
                      <inertial pos="0.00591597 -2.75379e-08 0.0190796" quat="0.6873 0.166308 0.166321 0.687239" mass="0.011" diaginertia="1.06828e-06 1.04938e-06 1.11406e-07" />
                      <joint name="revo2_right_middle_distal_joint" pos="0 0 0" axis="0 1 0" range="0 1.63" actuatorfrcrange="-7.0 7.0" damping="0.55" armature="0.012" />
                      <geom type="mesh" rgba="0.04 0.1 0.22 1" mesh="right_middle_distal_link" contype="1" conaffinity="1" friction="5.2 0.95 0.100" condim="4" solref="0.008 1" solimp="0.93 0.998 0.001" />
                      <geom pos="0.0159759 0 0.0265894" quat="0.971858 0 0.235566 0" type="mesh" rgba="0.18 0.18 0.2 1" mesh="right_middle_touch_link" contype="1" conaffinity="1" friction="5.2 0.95 0.100" condim="4" solref="0.008 1" solimp="0.93 0.998 0.001" />
                      <geom size="0.011 0.009 0.013" pos="0.0151136 0 0.0292832" quat="0.971858 0 0.235566 0" type="box" rgba="0.18 0.18 0.2 1" contype="1" conaffinity="1" friction="5.2 0.95 0.100" condim="4" solref="0.008 1" solimp="0.93 0.998 0.001" />
                    <geom name="stage4_middle_tip_marker" type="sphere" pos="0.0151136 0 0.0292832" size="0.014" rgba="0 0 0 0" contype="0" conaffinity="0" /><geom name="video2sim_revo2_right_middle_distal_link_contact_pad" type="sphere" group="5" pos="0.0151 0.0000 0.0293" size="0.021000" rgba="0.05 0.05 0.05 0.0" contype="1" conaffinity="1" friction="9.0 1.55 0.200" condim="4" solref="0.008 1" solimp="0.995 0.9999 0.0001" /><geom name="video2sim_revo2_right_middle_distal_link_contact_pad_extra_0" type="sphere" group="5" pos="0.015100 0.000000 0.015300" size="0.014000" rgba="0.05 0.05 0.05 0.0" contype="1" conaffinity="1" friction="9.0 1.55 0.200" condim="4" solref="0.014 1" solimp="0.96 0.999 0.001" /><geom name="video2sim_revo2_right_middle_distal_link_contact_pad_extra_1" type="sphere" group="5" pos="0.015100 0.000000 0.043300" size="0.014000" rgba="0.05 0.05 0.05 0.0" contype="1" conaffinity="1" friction="9.0 1.55 0.200" condim="4" solref="0.014 1" solimp="0.96 0.999 0.001" /></body>
                  <geom name="video2sim_revo2_right_middle_proximal_link_contact_pad" type="sphere" group="5" pos="-0.0021 0.0000 0.0201" size="0.020000" rgba="0.05 0.05 0.05 0.0" contype="1" conaffinity="1" friction="9.0 1.55 0.200" condim="4" solref="0.008 1" solimp="0.995 0.9999 0.0001" /></body>
                  <body name="revo2_right_ring_proximal_link" pos="0.0104001 0.00379441 0.249382" quat="0.356089 -0.0617138 0.0445464 0.931347" gravcomp="1">
                    <inertial pos="-0.00234495 5.87955e-06 0.0191774" quat="0.999831 0.000632097 0.0183324 0.000717657" mass="0.009" diaginertia="3.14463e-07 2.97613e-07 1.01829e-07" />
                    <joint name="revo2_right_ring_proximal_joint" pos="0 0 0" axis="0 1 0" range="0 1.41" actuatorfrcrange="-7.0 7.0" damping="0.55" armature="0.012" />
                    <geom type="mesh" rgba="0.04 0.1 0.22 1" mesh="right_ring_proximal_link" contype="1" conaffinity="1" friction="5.2 0.95 0.100" condim="4" solref="0.008 1" solimp="0.93 0.998 0.001" />
                    <body name="revo2_right_ring_distal_link" pos="0 0 0.035" gravcomp="1">
                      <inertial pos="0.00570078 5.57858e-08 0.0185997" quat="0.686867 0.167968 0.167968 0.686867" mass="0.011" diaginertia="1.01271e-06 9.96672e-07 1.02706e-07" />
                      <joint name="revo2_right_ring_distal_joint" pos="0 0 0" axis="0 1 0" range="0 1.63" actuatorfrcrange="-7.0 7.0" damping="0.55" armature="0.012" />
                      <geom type="mesh" rgba="0.04 0.1 0.22 1" mesh="right_ring_distal_link" contype="1" conaffinity="1" friction="5.2 0.95 0.100" condim="4" solref="0.008 1" solimp="0.93 0.998 0.001" />
                      <geom pos="0.0154392 0 0.0260561" quat="0.971858 0 0.235566 0" type="mesh" rgba="0.18 0.18 0.2 1" mesh="right_ring_touch_link" contype="1" conaffinity="1" friction="5.2 0.95 0.100" condim="4" solref="0.008 1" solimp="0.93 0.998 0.001" />
                    <geom name="video2sim_revo2_right_ring_distal_link_contact_pad" type="sphere" group="5" pos="0.0141 0.0000 0.0302" size="0.021000" rgba="0.05 0.05 0.05 0.0" contype="1" conaffinity="1" friction="9.0 1.55 0.200" condim="4" solref="0.008 1" solimp="0.995 0.9999 0.0001" /><geom name="video2sim_revo2_right_ring_distal_link_contact_pad_extra_0" type="sphere" group="5" pos="0.014100 0.000000 0.016200" size="0.014000" rgba="0.05 0.05 0.05 0.0" contype="1" conaffinity="1" friction="9.0 1.55 0.200" condim="4" solref="0.014 1" solimp="0.96 0.999 0.001" /><geom name="video2sim_revo2_right_ring_distal_link_contact_pad_extra_1" type="sphere" group="5" pos="0.014100 0.000000 0.044200" size="0.014000" rgba="0.05 0.05 0.05 0.0" contype="1" conaffinity="1" friction="9.0 1.55 0.200" condim="4" solref="0.014 1" solimp="0.96 0.999 0.001" /></body>
                  <geom name="video2sim_revo2_right_ring_proximal_link_contact_pad" type="sphere" group="5" pos="-0.0022 0.0000 0.0190" size="0.020000" rgba="0.05 0.05 0.05 0.0" contype="1" conaffinity="1" friction="9.0 1.55 0.200" condim="4" solref="0.008 1" solimp="0.995 0.9999 0.0001" /></body>
                  <body name="revo2_right_pinky_proximal_link" pos="0.0224313 0.0190985 0.244094" quat="0.30376 -0.0511895 0.0779066 0.948177" gravcomp="1">
                    <inertial pos="-0.00213212 7.75039e-06 0.0160672" quat="0.999803 0.000555178 0.0198191 0.000562874" mass="0.009" diaginertia="1.97745e-07 1.82023e-07 8.19805e-08" />
                    <joint name="revo2_right_pinky_proximal_joint" pos="0 0 0" axis="0 1 0" range="0 1.41" actuatorfrcrange="-7.0 7.0" damping="0.55" armature="0.012" />
                    <geom type="mesh" rgba="0.04 0.1 0.22 1" mesh="right_pinky_proximal_link" contype="1" conaffinity="1" friction="5.2 0.95 0.100" condim="4" solref="0.008 1" solimp="0.93 0.998 0.001" />
                    <body name="revo2_right_pinky_distal_link" pos="0 0 0.029" gravcomp="1">
                      <inertial pos="0.00473738 -1.62934e-07 0.0150053" quat="0.682052 0.186478 0.186456 0.682103" mass="0.011" diaginertia="6.20818e-07 6.07614e-07 8.1918e-08" />
                      <joint name="revo2_right_pinky_distal_joint" pos="0 0 0" axis="0 1 0" range="0 1.63" actuatorfrcrange="-7.0 7.0" damping="0.55" armature="0.012" />
                      <geom type="mesh" rgba="0.04 0.1 0.22 1" mesh="right_pinky_distal_link" contype="1" conaffinity="1" friction="5.2 0.95 0.100" condim="4" solref="0.008 1" solimp="0.93 0.998 0.001" />
                      <geom pos="0.01401 0 0.021124" quat="0.971859 0 0.235565 0" type="mesh" rgba="0.18 0.18 0.2 1" mesh="right_pinky_touch_link" contype="1" conaffinity="1" friction="5.2 0.95 0.100" condim="4" solref="0.008 1" solimp="0.93 0.998 0.001" />
                    <geom name="video2sim_revo2_right_pinky_distal_link_contact_pad" type="sphere" group="5" pos="0.0122 0.0000 0.0239" size="0.021000" rgba="0.05 0.05 0.05 0.0" contype="1" conaffinity="1" friction="9.0 1.55 0.200" condim="4" solref="0.008 1" solimp="0.995 0.9999 0.0001" /><geom name="video2sim_revo2_right_pinky_distal_link_contact_pad_extra_0" type="sphere" group="5" pos="0.012200 0.000000 0.009900" size="0.014000" rgba="0.05 0.05 0.05 0.0" contype="1" conaffinity="1" friction="9.0 1.55 0.200" condim="4" solref="0.014 1" solimp="0.96 0.999 0.001" /><geom name="video2sim_revo2_right_pinky_distal_link_contact_pad_extra_1" type="sphere" group="5" pos="0.012200 0.000000 0.037900" size="0.014000" rgba="0.05 0.05 0.05 0.0" contype="1" conaffinity="1" friction="9.0 1.55 0.200" condim="4" solref="0.014 1" solimp="0.96 0.999 0.001" /></body>
                  <geom name="video2sim_revo2_right_pinky_proximal_link_contact_pad" type="sphere" group="5" pos="-0.0020 0.0000 0.0158" size="0.020000" rgba="0.05 0.05 0.05 0.0" contype="1" conaffinity="1" friction="9.0 1.55 0.200" condim="4" solref="0.008 1" solimp="0.995 0.9999 0.0001" /></body>
                <geom name="video2sim_revo2_palm_contact_pad" type="box" group="5" pos="-0.006500 -0.001000 0.092000" size="0.048000 0.036000 0.008000" rgba="0.05 0.05 0.05 0.0" contype="1" conaffinity="1" friction="5.5 1.05 0.130" condim="4" solref="0.008 1" solimp="0.995 0.9999 0.0001" /></body>
              </body>
            </body>
          </body>
        </body>
      </body>
    </body>
  <light pos="0 -2 4" dir="0 0 -1" diffuse="0.9 0.9 0.9" /><camera name="front_arc" pos="0 -1.9 1.15" xyaxes="1 0 0 0 0.50 0.86" fovy="48" /><camera name="top_oblique" pos="0.0 -1.25 1.75" xyaxes="1 0 0 0 0.84 0.54" fovy="52" /><geom name="floor" type="plane" size="2 2 0.02" rgba="1 1 1 1" friction="0.8 0.01 0.001" material="video2sim_warm_wood_floor_mat" /><camera name="front" pos="0.000000 -2.750000 1.300000" xyaxes="0.997570 -0.069672 0.000000 0.010471 0.149919 0.988643" fovy="54" /><camera name="top" pos="0.000000 0.120000 3.150000" xyaxes="0.780869 -0.624695 0.000000 0.621442 0.776803 0.101917" fovy="58" /><camera name="left" pos="-2.150000 0.220000 1.220000" xyaxes="0.050997 -0.998699 0.000000 0.183565 0.009374 0.982963" fovy="54" /><camera name="right" pos="2.150000 0.220000 1.220000" xyaxes="0.061422 0.998112 -0.000000 -0.219297 0.013495 0.975565" fovy="54" /><camera name="left_oblique" pos="-1.600000 -1.750000 1.450000" xyaxes="0.757719 -0.652581 0.000000 0.154036 0.178853 0.971743" fovy="56" /><camera name="right_oblique" pos="1.600000 -1.750000 1.450000" xyaxes="0.830825 0.556534 -0.000000 -0.143234 0.213829 0.966313" fovy="56" /><geom name="video2sim_indoor_back_wall" type="box" pos="0 2.55 1.45" size="5.0 0.035 1.65" material="video2sim_soft_indoor_wall_mat" contype="0" conaffinity="0" /><geom name="video2sim_indoor_front_wall" type="box" pos="0 -2.95 1.45" size="5.0 0.035 1.65" material="video2sim_soft_indoor_wall_mat" contype="0" conaffinity="0" /><geom name="video2sim_indoor_left_wall" type="box" pos="-3.05 -0.10 1.45" size="0.035 2.85 1.65" material="video2sim_soft_indoor_wall_mat" contype="0" conaffinity="0" /><geom name="video2sim_indoor_right_wall" type="box" pos="3.05 -0.10 1.45" size="0.035 2.85 1.65" material="video2sim_soft_indoor_wall_mat" contype="0" conaffinity="0" /><geom name="video2sim_indoor_ceiling_bounce" type="box" pos="0 0.10 3.75" size="5.0 3.0 0.025" rgba="0.82 0.80 0.74 1" contype="0" conaffinity="0" /><light name="large_soft_key" pos="0 -1.5 4.0" dir="0.04 0.12 -1" diffuse="1.15 1.08 0.92" specular="0.32 0.30 0.26" directional="true" /><light name="overhead_room_light" pos="0.0 0.15 2.45" diffuse="0.75 0.70 0.62" specular="0.18 0.16 0.14" directional="false" /><light name="side_fill" pos="-1.5 -0.8 2.3" diffuse="0.55 0.58 0.60" specular="0.08 0.08 0.08" directional="false" /><light name="right_rim_fill" pos="1.55 -0.65 1.90" diffuse="0.35 0.38 0.42" specular="0.10 0.10 0.12" directional="false" /><body name="incoming_object" pos="-0.55 -0.42 0.96" quat="1 0 0 0"><freejoint name="incoming_object_free" /><inertial pos="0 0 0" mass="0.002284" diaginertia="0.00000108 0.00000108 0.00000108" /><geom name="incoming_object_geom" type="sphere" size="0.034341" rgba="0.5396 0.4810 0.2878 1.0000" friction="8.5 1.45 0.180" condim="4" solref="0.012 1" solimp="0.995 0.9999 0.0001" /></body></worldbody>
<visual><global offwidth="1600" offheight="912" /><quality shadowsize="4096" /></visual><actuator><position name="panda_joint1_pos" joint="panda_joint1" kp="220" ctrllimited="true" ctrlrange="-2.8973 2.8973" /><position name="panda_joint2_pos" joint="panda_joint2" kp="220" ctrllimited="true" ctrlrange="-1.7628 1.7628" /><position name="panda_joint3_pos" joint="panda_joint3" kp="220" ctrllimited="true" ctrlrange="-2.8973 2.8973" /><position name="panda_joint4_pos" joint="panda_joint4" kp="220" ctrllimited="true" ctrlrange="-3.0718 -0.0698" /><position name="panda_joint5_pos" joint="panda_joint5" kp="220" ctrllimited="true" ctrlrange="-2.8973 2.8973" /><position name="panda_joint6_pos" joint="panda_joint6" kp="220" ctrllimited="true" ctrlrange="-0.0175 3.7525" /><position name="panda_joint7_pos" joint="panda_joint7" kp="220" ctrllimited="true" ctrlrange="-2.8973 2.8973" /><position name="revo2_right_thumb_metacarpal_joint_pos" joint="revo2_right_thumb_metacarpal_joint" kp="340" ctrllimited="true" ctrlrange="0 1.57" /><position name="revo2_right_thumb_proximal_joint_pos" joint="revo2_right_thumb_proximal_joint" kp="340" ctrllimited="true" ctrlrange="0 1.03" /><position name="revo2_right_thumb_distal_joint_pos" joint="revo2_right_thumb_distal_joint" kp="340" ctrllimited="true" ctrlrange="0 1.03" /><position name="revo2_right_index_proximal_joint_pos" joint="revo2_right_index_proximal_joint" kp="340" ctrllimited="true" ctrlrange="0 1.41" /><position name="revo2_right_index_distal_joint_pos" joint="revo2_right_index_distal_joint" kp="340" ctrllimited="true" ctrlrange="0 1.63" /><position name="revo2_right_middle_proximal_joint_pos" joint="revo2_right_middle_proximal_joint" kp="340" ctrllimited="true" ctrlrange="0 1.41" /><position name="revo2_right_middle_distal_joint_pos" joint="revo2_right_middle_distal_joint" kp="340" ctrllimited="true" ctrlrange="0 1.63" /><position name="revo2_right_ring_proximal_joint_pos" joint="revo2_right_ring_proximal_joint" kp="340" ctrllimited="true" ctrlrange="0 1.41" /><position name="revo2_right_ring_distal_joint_pos" joint="revo2_right_ring_distal_joint" kp="340" ctrllimited="true" ctrlrange="0 1.63" /><position name="revo2_right_pinky_proximal_joint_pos" joint="revo2_right_pinky_proximal_joint" kp="340" ctrllimited="true" ctrlrange="0 1.41" /><position name="revo2_right_pinky_distal_joint_pos" joint="revo2_right_pinky_distal_joint" kp="340" ctrllimited="true" ctrlrange="0 1.63" /></actuator></mujoco>