<mujoco model="franka_brainco_revo2_right">
  <compiler angle="radian" />

  <asset>
    <mesh name="link0" file="link0_visual_clean_v718.stl" />
    <mesh name="link1" file="link1_visual_clean_v718.stl" />
    <mesh name="link2" file="link2_visual_clean_v718.stl" />
    <mesh name="link3" file="link3_visual_clean_v718.stl" />
    <mesh name="link4" file="link4_visual_clean_v718.stl" />
    <mesh name="link5" file="link5_visual_clean_v718.stl" />
    <mesh name="link6" file="link6_visual_clean_v718.stl" />
    <mesh name="link7" file="link7_visual_clean_v718.stl" />
    <mesh name="right_base_link" file="right_base_link.STL" />
    <mesh name="right_thumb_metacarpal_link" file="right_thumb_metacarpal_link.STL" />
    <mesh name="right_thumb_proximal_link" file="right_thumb_proximal_link.STL" />
    <mesh name="right_thumb_distal_link" file="right_thumb_distal_link.STL" />
    <mesh name="right_thumb_touch_link" file="right_thumb_touch_link.STL" />
    <mesh name="right_index_proximal_link" file="right_index_proximal_link.STL" />
    <mesh name="right_index_distal_link" file="right_index_distal_link.STL" />
    <mesh name="right_index_touch_link" file="right_index_touch_link.STL" />
    <mesh name="right_middle_proximal_link" file="right_middle_proximal_link.STL" />
    <mesh name="right_middle_distal_link" file="right_middle_distal_link.STL" />
    <mesh name="right_middle_touch_link" file="right_middle_touch_link.STL" />
    <mesh name="right_ring_proximal_link" file="right_ring_proximal_link.STL" />
    <mesh name="right_ring_distal_link" file="right_ring_distal_link.STL" />
    <mesh name="right_ring_touch_link" file="right_ring_touch_link.STL" />
    <mesh name="right_pinky_proximal_link" file="right_pinky_proximal_link.STL" />
    <mesh name="right_pinky_distal_link" file="right_pinky_distal_link.STL" />
    <mesh name="right_pinky_touch_link" file="right_pinky_touch_link.STL" />
  </asset>

  <worldbody>
    <geom type="mesh" mesh="link0" />
    <body name="panda_link1" pos="0 0 0.333">
      <joint name="panda_joint1" pos="0 0 0" axis="0 0 1" range="-2.8973 2.8973" actuatorfrcrange="-87 87" />
      <geom type="mesh" mesh="link1" />
      <body name="panda_link2" quat="0.707107 -0.707107 0 0">
        <joint name="panda_joint2" pos="0 0 0" axis="0 0 1" range="-1.7628 1.7628" actuatorfrcrange="-87 87" />
        <geom type="mesh" mesh="link2" />
        <body name="panda_link3" pos="0 -0.316 0" quat="0.707107 0.707107 0 0">
          <joint name="panda_joint3" pos="0 0 0" axis="0 0 1" range="-2.8973 2.8973" actuatorfrcrange="-87 87" />
          <geom type="mesh" mesh="link3" />
          <body name="panda_link4" pos="0.0825 0 0" quat="0.707107 0.707107 0 0">
            <joint name="panda_joint4" pos="0 0 0" axis="0 0 1" range="-3.0718 -0.0698" actuatorfrcrange="-87 87" />
            <geom type="mesh" mesh="link4" />
            <body name="panda_link5" pos="-0.0825 0.384 0" quat="0.707107 -0.707107 0 0">
              <joint name="panda_joint5" pos="0 0 0" axis="0 0 1" range="-2.8973 2.8973" actuatorfrcrange="-12 12" />
              <geom type="mesh" mesh="link5" />
              <body name="panda_link6" quat="0.707107 0.707107 0 0">
                <joint name="panda_joint6" pos="0 0 0" axis="0 0 1" range="-0.0175 3.7525" actuatorfrcrange="-12 12" />
                <geom type="mesh" mesh="link6" />
                <body name="panda_link7" pos="0.088 0 0" quat="0.707107 0.707107 0 0">
                  <joint name="panda_joint7" pos="0 0 0" axis="0 0 1" range="-2.8973 2.8973" actuatorfrcrange="-12 12" />
                  <geom type="mesh" mesh="link7" />
                  <geom size="0.034 0.004" pos="0 0 0.111" quat="0.92388 0 0 -0.382683" type="cylinder" rgba="0.35 0.35 0.35 1" />
                  <geom size="0.018 0.0212" pos="0 0 0.1362" quat="0.92388 0 0 -0.382683" type="cylinder" rgba="0.35 0.35 0.35 1" />
                  <geom size="0.028 0.004" pos="0 0 0.1614" quat="0.92388 0 0 -0.382683" type="cylinder" rgba="0.35 0.35 0.35 1" />
                  <geom pos="0 0 0.1654" quat="0.382683 0 0 0.92388" type="mesh" rgba="0.04 0.1 0.22 1" mesh="right_base_link" />
                  <body name="revo2_right_thumb_metacarpal_link" pos="-0.0180213 -0.0100749 0.193225" quat="0.458791 0 0 0.888544">
                    <inertial pos="1.51106e-05 0.00707243 -0.00420847" quat="0.465075 -0.0302438 0.0586743 0.882807" mass="0.01" diaginertia="1.66115e-07 1.56006e-07 4.9387e-08" />
                    <joint name="revo2_right_thumb_metacarpal_joint" pos="0 0 0" axis="0 0 -1" range="0 1.57" actuatorfrcrange="-0.5 0.5" />
                    <geom type="mesh" rgba="0.04 0.1 0.22 1" mesh="right_thumb_metacarpal_link" />
                    <body name="revo2_right_thumb_proximal_link" pos="0 0.014227 0" quat="0.986557 0.0765206 0.124804 0.0726253">
                      <inertial pos="-4.6972e-07 0.0277015 -0.00202656" quat="0.496496 0.503512 -0.503514 0.496429" mass="0.05" diaginertia="2.56295e-06 2.40452e-06 5.11916e-07" />
                      <joint name="revo2_right_thumb_proximal_joint" pos="0 0 0" axis="1 0 0" range="0 1.03" actuatorfrcrange="-1.1 1.1" />
                      <geom type="mesh" rgba="0.04 0.1 0.22 1" mesh="right_thumb_proximal_link" />
                      <body name="revo2_right_thumb_distal_link" pos="0 0.052 0">
                        <inertial pos="-6.86982e-09 0.0117545 1.13288e-05" quat="0.528527 0.469685 -0.46966 0.528654" mass="0.012" diaginertia="4.42072e-07 3.35587e-07 2.27759e-07" />
                        <joint name="revo2_right_thumb_distal_joint" pos="0 0 0" axis="1 0 0" range="0 1.03" actuatorfrcrange="-1.1 1.1" />
                        <geom type="mesh" rgba="0.04 0.1 0.22 1" mesh="right_thumb_distal_link" />
                        <geom pos="0 0.0137928 0.0076766" quat="0.999443 -0.033369 0 0" type="mesh" rgba="0.18 0.18 0.2 1" mesh="right_thumb_touch_link" />
                        <geom size="0.012 0.009 0.013" pos="0 0.0127283 0.00674553" quat="0.999443 -0.033369 0 0" type="box" rgba="0.18 0.18 0.2 1" />
                      </body>
                    </body>
                  </body>
                  <body name="revo2_right_index_proximal_link" pos="-0.01941 -0.0224055 0.246276" quat="0.455694 -0.092407 -0.018312 0.885138">
                    <inertial pos="-0.00223495 3.15875e-06 0.0176402" quat="0.9998 0.000578854 0.0200071 0.00015863" mass="0.009" diaginertia="2.52201e-07 2.36436e-07 9.27798e-08" />
                    <joint name="revo2_right_index_proximal_joint" pos="0 0 0" axis="0 1 0" range="0 1.41" actuatorfrcrange="-2 2" />
                    <geom type="mesh" rgba="0.04 0.1 0.22 1" mesh="right_index_proximal_link" />
                    <body name="revo2_right_index_distal_link" pos="0 0 0.032">
                      <inertial pos="0.00506251 1.61615e-07 0.0165189" quat="0.684726 0.176495 0.176496 0.684726" mass="0.011" diaginertia="7.85555e-07 7.71534e-07 8.73346e-08" />
                      <joint name="revo2_right_index_distal_joint" pos="0 0 0" axis="0 1 0" range="0 1.63" actuatorfrcrange="-2 2" />
                      <geom type="mesh" rgba="0.04 0.1 0.22 1" mesh="right_index_distal_link" />
                      <geom pos="0.014497 0 0.023303" quat="0.6361 0.734769 0.154182 -0.178098" type="mesh" rgba="0.18 0.18 0.2 1" mesh="right_index_touch_link" />
                      <geom size="0.011 0.009 0.013" pos="0.0131721 -0.00014321 0.0250986" quat="0.6361 0.734769 0.154182 -0.178098" type="box" rgba="0.18 0.18 0.2 1" />
                    </body>
                  </body>
                  <body name="revo2_right_middle_proximal_link" pos="-0.00387091 -0.0103433 0.250393" quat="0.406762 -0.0756337 0.0123612 0.910314">
                    <inertial pos="-0.00222511 5.25632e-06 0.0203008" quat="0.999816 0.00054813 0.0191911 0.000563992" mass="0.009" diaginertia="3.67373e-07 3.52646e-07 1.11857e-07" />
                    <joint name="revo2_right_middle_proximal_joint" pos="0 0 0" axis="0 1 0" range="0 1.41" actuatorfrcrange="-2 2" />
                    <geom type="mesh" rgba="0.04 0.1 0.22 1" mesh="right_middle_proximal_link" />
                    <body name="revo2_right_middle_distal_link" pos="0 0 0.037">
                      <inertial pos="0.00591597 -2.75379e-08 0.0190796" quat="0.6873 0.166308 0.166321 0.687239" mass="0.011" diaginertia="1.06828e-06 1.04938e-06 1.11406e-07" />
                      <joint name="revo2_right_middle_distal_joint" pos="0 0 0" axis="0 1 0" range="0 1.63" actuatorfrcrange="-2 2" />
                      <geom type="mesh" rgba="0.04 0.1 0.22 1" mesh="right_middle_distal_link" />
                      <geom pos="0.0159759 0 0.0265894" quat="0.971858 0 0.235566 0" type="mesh" rgba="0.18 0.18 0.2 1" mesh="right_middle_touch_link" />
                      <geom size="0.011 0.009 0.013" pos="0.0151136 0 0.0292832" quat="0.971858 0 0.235566 0" type="box" rgba="0.18 0.18 0.2 1" />
                    </body>
                  </body>
                  <body name="revo2_right_ring_proximal_link" pos="0.0104001 0.00379441 0.249382" quat="0.356089 -0.0617138 0.0445464 0.931347">
                    <inertial pos="-0.00234495 5.87955e-06 0.0191774" quat="0.999831 0.000632097 0.0183324 0.000717657" mass="0.009" diaginertia="3.14463e-07 2.97613e-07 1.01829e-07" />
                    <joint name="revo2_right_ring_proximal_joint" pos="0 0 0" axis="0 1 0" range="0 1.41" actuatorfrcrange="-2 2" />
                    <geom type="mesh" rgba="0.04 0.1 0.22 1" mesh="right_ring_proximal_link" />
                    <body name="revo2_right_ring_distal_link" pos="0 0 0.035">
                      <inertial pos="0.00570078 5.57858e-08 0.0185997" quat="0.686867 0.167968 0.167968 0.686867" mass="0.011" diaginertia="1.01271e-06 9.96672e-07 1.02706e-07" />
                      <joint name="revo2_right_ring_distal_joint" pos="0 0 0" axis="0 1 0" range="0 1.63" actuatorfrcrange="-2 2" />
                      <geom type="mesh" rgba="0.04 0.1 0.22 1" mesh="right_ring_distal_link" />
                      <geom pos="0.0154392 0 0.0260561" quat="0.971858 0 0.235566 0" type="mesh" rgba="0.18 0.18 0.2 1" mesh="right_ring_touch_link" />
                    </body>
                  </body>
                  <body name="revo2_right_pinky_proximal_link" pos="0.0224313 0.0190985 0.244094" quat="0.30376 -0.0511895 0.0779066 0.948177">
                    <inertial pos="-0.00213212 7.75039e-06 0.0160672" quat="0.999803 0.000555178 0.0198191 0.000562874" mass="0.009" diaginertia="1.97745e-07 1.82023e-07 8.19805e-08" />
                    <joint name="revo2_right_pinky_proximal_joint" pos="0 0 0" axis="0 1 0" range="0 1.41" actuatorfrcrange="-2 2" />
                    <geom type="mesh" rgba="0.04 0.1 0.22 1" mesh="right_pinky_proximal_link" />
                    <body name="revo2_right_pinky_distal_link" pos="0 0 0.029">
                      <inertial pos="0.00473738 -1.62934e-07 0.0150053" quat="0.682052 0.186478 0.186456 0.682103" mass="0.011" diaginertia="6.20818e-07 6.07614e-07 8.1918e-08" />
                      <joint name="revo2_right_pinky_distal_joint" pos="0 0 0" axis="0 1 0" range="0 1.63" actuatorfrcrange="-2 2" />
                      <geom type="mesh" rgba="0.04 0.1 0.22 1" mesh="right_pinky_distal_link" />
                      <geom pos="0.01401 0 0.021124" quat="0.971859 0 0.235565 0" type="mesh" rgba="0.18 0.18 0.2 1" mesh="right_pinky_touch_link" />
                    </body>
                  </body>
                </body>
              </body>
            </body>
          </body>
        </body>
      </body>
    </body>
  </worldbody>
</mujoco>